<?xml version="1.0"?>

<robot xmlns:xacro="http://ros.org/wiki/xacro">

  <xacro:macro name="bluerov2_heavy_modified_urdf" params="prefix">

    <link name="base_footprint" />

    <link name="${prefix}base_link">
      <inertial>
        <origin rpy="0 0 0" xyz="0.0 0.0 0.011" />
        <mass value="13.0" />
        <inertia
          ixx="0.26"
          ixy="0"
          ixz="0"
          iyy="0.23"
          iyz="0"
          izz="0.37"
        />
      </inertial>
      <visual>
        <geometry>
          <mesh
            filename="package://angler_description/meshes/bluerov2_heavy_modified.dae"
            scale="0.025 0.025 0.025"
          />
        </geometry>
        <origin rpy="0 0 0" xyz="0 0 0" />
      </visual>
      <collision>
        <geometry>
          <box size="0.457 0.575 0.05" />
        </geometry>
        <origin rpy="0 0 0" xyz="0 0 0.06" />
      </collision>
    </link>

    <link name="${prefix}thruster1">
      <inertial>
        <mass value="0.002" />
        <inertia
          ixx="0.001"
          ixy="0"
          ixz="0"
          iyy="0.001"
          iyz="0"
          izz="0.001"
        />
      </inertial>
      <visual>
        <geometry>
          <mesh filename="package://angler_description/meshes/t200_ccw_prop.dae" />
        </geometry>
        <origin rpy="-1.571 0 0" xyz="0 0 0" />
      </visual>
    </link>

    <link name="${prefix}thruster2">
      <inertial>
        <mass value="0.002" />
        <inertia
          ixx="0.001"
          ixy="0"
          ixz="0"
          iyy="0.001"
          iyz="0"
          izz="0.001"
        />
      </inertial>
      <visual>
        <geometry>
          <mesh filename="package://angler_description/meshes/t200_ccw_prop.dae" />
        </geometry>
        <origin rpy="-1.571 0 0" xyz="0 0 0" />
      </visual>
    </link>

    <link name="${prefix}thruster3">
      <inertial>
        <mass value="0.002" />
        <inertia
          ixx="0.001"
          ixy="0"
          ixz="0"
          iyy="0.001"
          iyz="0"
          izz="0.001"
        />
      </inertial>
      <visual>
        <geometry>
          <mesh filename="package://angler_description/meshes/t200_cw_prop.dae" />
        </geometry>
        <origin rpy="1.571 0 0" xyz="0 0 0" />
      </visual>
    </link>

    <link name="${prefix}thruster4">
      <inertial>
        <mass value="0.002" />
        <inertia
          ixx="0.001"
          ixy="0"
          ixz="0"
          iyy="0.001"
          iyz="0"
          izz="0.001"
        />
      </inertial>
      <visual>
        <geometry>
          <mesh filename="package://angler_description/meshes/t200_cw_prop.dae" />
        </geometry>
        <origin rpy="1.571 0 0" xyz="0 0 0" />
      </visual>
    </link>

    <link name="${prefix}thruster5">
      <inertial>
        <mass value="0.002" />
        <inertia
          ixx="0.001"
          ixy="0"
          ixz="0"
          iyy="0.001"
          iyz="0"
          izz="0.001"
        />
      </inertial>
      <visual>
        <geometry>
          <mesh filename="package://angler_description/meshes/t200_ccw_prop.dae" />
        </geometry>
        <origin rpy="-1.571 0 1.571" xyz="0 0 0" />
      </visual>
    </link>

    <link name="${prefix}thruster6">
      <inertial>
        <mass value="0.002" />
        <inertia
          ixx="0.001"
          ixy="0"
          ixz="0"
          iyy="0.001"
          iyz="0"
          izz="0.001"
        />
      </inertial>
      <visual>
        <geometry>
          <mesh filename="package://angler_description/meshes/t200_cw_prop.dae" />
        </geometry>
        <origin rpy="1.571 0 1.571" xyz="0 0 0" />
      </visual>
    </link>

    <link name="${prefix}thruster7">
      <inertial>
        <mass value="0.002" />
        <inertia
          ixx="0.001"
          ixy="0"
          ixz="0"
          iyy="0.001"
          iyz="0"
          izz="0.001"
        />
      </inertial>
      <visual>
        <geometry>
          <mesh filename="package://angler_description/meshes/t200_cw_prop.dae" />
        </geometry>
        <origin rpy="1.571 0 1.571" xyz="0 0 0" />
      </visual>
    </link>

    <link name="${prefix}thruster8">
      <inertial>
        <mass value="0.002" />
        <inertia
          ixx="0.001"
          ixy="0"
          ixz="0"
          iyy="0.001"
          iyz="0"
          izz="0.001"
        />
      </inertial>
      <visual>
        <geometry>
          <mesh filename="package://angler_description/meshes/t200_ccw_prop.dae" />
        </geometry>
        <origin rpy="-1.571 0 1.571" xyz="0 0 0" />
      </visual>
    </link>

    <link name="${prefix}manipulator_mount_link">
      <visual>
        <origin rpy="0 0 0" xyz="0 0 0" />
        <geometry>
          <box size="0.001 0.001 0.001" />
        </geometry>
      </visual>
      <inertial>
        <mass value="0.0001" />
        <inertia
          ixx="0.0001"
          ixy="0"
          ixz="0"
          iyy="0.0001"
          iyz="0"
          izz="0.0001"
        />
      </inertial>
    </link>

    <joint name="base_footprint_joint" type="fixed">
      <parent link="base_footprint" />
      <child link="base_link" />
    </joint>

    <joint name="${prefix}thruster1_joint" type="continuous">
      <parent link="${prefix}base_link" />
      <child link="${prefix}thruster1" />
      <axis xyz="0 0 -1" />
      <origin rpy="-1.571 1.571 -1.047" xyz="0.088 -0.102 -0.04" />
      <limits effort="-1" velocity="-1" />
    </joint>

    <joint name="${prefix}thruster2_joint" type="continuous">
      <parent link="${prefix}base_link" />
      <child link="${prefix}thruster2" />
      <axis xyz="0 0 -1" />
      <origin rpy="-1.571 1.571 -2.094" xyz="0.088 0.102 -0.04" />
      <limits effort="-1" velocity="-1" />
    </joint>

    <joint name="${prefix}thruster3_joint" type="continuous">
      <parent link="${prefix}base_link" />
      <child link="${prefix}thruster3" />
      <axis xyz="0 0 -1" />
      <origin rpy="-1.571 1.571 1.047" xyz="-0.088 -0.102 -0.04" />
      <limits effort="-1" velocity="-1" />
    </joint>

    <joint name="${prefix}thruster4_joint" type="continuous">
      <parent link="${prefix}base_link" />
      <child link="${prefix}thruster4" />
      <axis xyz="0 0 -1" />
      <origin rpy="-1.571 1.571 2.094" xyz="-0.088 0.102 -0.04" />
      <limits effort="-1" velocity="-1" />
    </joint>

    <joint name="${prefix}thruster5_joint" type="continuous">
      <parent link="${prefix}base_link" />
      <child link="${prefix}thruster5" />
      <axis xyz="0 0 -1" />
      <origin rpy="0 0 0" xyz="0.118 -0.215 0.064" />
      <limits effort="-1" velocity="-1" />
    </joint>

    <joint name="${prefix}thruster6_joint" type="continuous">
      <parent link="${prefix}base_link" />
      <child link="${prefix}thruster6" />
      <axis xyz="0 0 -1" />
      <origin rpy="0 0 0" xyz="0.118 0.215 0.064" />
      <limits effort="-1" velocity="-1" />
    </joint>

    <joint name="${prefix}thruster7_joint" type="continuous">
      <parent link="${prefix}base_link" />
      <child link="${prefix}thruster7" />
      <axis xyz="0 0 -1" />
      <origin rpy="0 0 0" xyz="-0.118 -0.215 0.064" />
      <limits effort="-1" velocity="-1" />
    </joint>

    <joint name="${prefix}thruster8_joint" type="continuous">
      <parent link="${prefix}base_link" />
      <child link="${prefix}thruster8" />
      <axis xyz="0 0 -1" />
      <origin rpy="0 0 0" xyz="-0.118 0.215 0.064" />
      <limits effort="-1" velocity="-1" />
    </joint>

    <joint name="${prefix}manipulator_mount_joint" type="fixed">
      <!-- The Alpha is mounted upside-down -->
      <origin rpy="0 0 0" xyz="0.24 -0.099 0.029" />
      <parent link="${prefix}base_link" />
      <child link="${prefix}manipulator_mount_link" />
    </joint>

    <!-- Import Alpha macro -->
    <xacro:include filename="$(find angler_description)/urdf/alpha.urdf.xacro" />

    <xacro:alpha_urdf parent="${prefix}manipulator_mount_link" prefix="${prefix}alpha_">
      <origin xyz="0 0 0" rpy="0 0 0" />
    </xacro:alpha_urdf>

  </xacro:macro>

</robot>
